File: Tensile.dat
MTS793|MPT|ENU|1|2|.|/|:|1|0|0|A

Data Acquisition						Time:	102.02344	s	12/20/2016 1:19:06 PM
Axial Displacement	Axial Displacement Error	Axial Extensometer	Axial Extensometer Abs. Error	Axial Force	Axial Force Abs. Error	Running Time	Time
mm	mm	mm/mm	mm/mm	N	N	s	s
-0.00061511993	-6.4190244e-05	-0.00016406666	0	681.18506	0	0.1015625	0.12011719
-0.0004029274	-0.00027638278	-0.00023296234	0	679.72717	0	0.30078125	0.31933594
-0.00082015991	0.00014084973	-0.00028680405	0	680.89185	0	0.5	0.51855469
-0.0008893013	0.00020999112	-0.00029476394	0	675.1734	0	0.69921875	0.71777344
-0.00019311905	-0.00048619113	-0.00016029953	0	674.552	0	0.8984375	0.91699219
-0.00055074692	-0.00012856326	-0.00012773962	0	673.95404	0	1.0976563	1.1162109
-0.0010061264	0.00032681623	-0.00015600417	0	673.94067	0	1.296875	1.3154297
-0.00023365021	-0.00044565997	-7.1672548e-05	0	677.41156	0	1.4960938	1.5146484
-0.00041246414	-0.00026684604	-0.00010274744	0	681.36981	0	1.6953125	1.7138672
0.00019788742	-0.0008771976	-0.00012762175	0	682.70648	0	1.8945313	1.9130859
-0.0011491776	0.00046986737	-0.00017893799	0	678.078	0	2.09375	2.1123047
-0.00010490417	-0.000574406	-0.00014249999	0	681.35822	0	2.2929688	2.3115234
-0.0010585785	0.00037926831	-3.3172546e-05	0	680.52252	0	2.4921875	2.5107422
-0.00044584274	-0.00023346744	-0.00010052136	0	679.27612	0	2.6914063	2.7099609
-0.00050783157	-0.0001714786	-0.0001076216	0	677.57422	0	2.890625	2.9091797
-0.00096559525	0.00028628507	-0.00019042745	0	674.79547	0	3.0898438	3.1083984
-0.00078201294	0.00010270276	-9.0738104e-05	0	676.08282	0	3.2890625	3.3076172
-0.00054836273	-0.00013094745	-4.1673047e-05	0	673.28284	0	3.4882813	3.5068359
-0.00064611435	-3.3195829e-05	-0.00012410019	0	674.26959	0	3.6875	3.7060547
-0.00062704086	-5.2269315e-05	-0.00010390904	0	674.91962	0	3.8867188	3.9052734
-0.00023603439	-0.00044327579	-0.00021799824	0	676.84515	0	4.0859375	4.1044922
-0.00036716461	-0.00031214557	-0.00011274205	0	677.13458	0	4.2851563	4.3037109
-0.00064611435	-3.3195829e-05	4.9332448e-05	0	678.40283	0	4.484375	4.5029297
-0.00018596649	-0.00049334369	-0.00010037984	0	678.75458	0	4.6835938	4.7021484
-0.00091075897	0.00023144879	-2.6747875e-05	0	675.65497	0	4.8828125	4.9013672
-0.00077486038	9.5550204e-05	-9.3260678e-05	0	678.41425	0	5.0820313	5.1005859
-0.0004863739	-0.00019293628	-0.00017879356	0	670.92914	0	5.28125	5.2998047
-0.00061750412	-6.1806059e-05	-0.00017439197	0	668.5705	0	5.4804688	5.4990234
-0.0010800362	0.00040072598	-0.00013953722	0	665.59473	0	5.6796875	5.6982422
-0.00095129013	0.00027197995	-7.5517164e-05	0	666.23474	0	5.8789063	5.8974609
-0.0011610985	0.0004817883	-0.00021658998	0	666.95215	0	6.078125	6.0966797
-0.0013160706	0.00063676038	-0.00015515361	0	669.24701	0	6.2773438	6.2958984
-0.00092744827	0.00024813809	-7.3281626e-05	0	667.93359	0	6.4765625	6.4951172
-0.0014472008	0.0007678906	-0.00024074543	0	666.69153	0	6.6757813	6.6943359
-0.0011229515	0.00044364133	-0.00014744801	0	666.97736	0	6.875	6.8935547
-0.0012183189	0.00053900876	-0.00030499214	0	671.29883	0	7.0742188	7.0927734
-0.0010323524	0.00035304227	-0.00019307081	0	673.67987	0	7.2734375	7.2919922
-0.00097751617	0.000298206	-0.00015868027	0	675.80127	0	7.4726563	7.4912109
-0.00029802322	-0.00038128695	-0.00011240045	0	678.64264	0	7.671875	7.6904297
-0.00026702881	-0.00041228137	-4.2444299e-06	0	680.21082	0	7.8710938	7.8896484
-0.0014400482	0.00076073804	-0.00011542143	0	681.15125	0	8.0703125	8.0888672
-0.00097513199	0.00029582181	-8.607276e-05	0	681.99921	0	8.2695313	8.2880859
-0.00054359436	-0.00013571582	-8.4839485e-05	0	682.26318	0	8.46875	8.4873047
-0.00018596649	-0.00049334369	-9.6917574e-05	0	680.81219	0	8.6679688	8.6865234
-0.00056743622	-0.00011187396	-0.00010890435	0	680.06122	0	8.8671875	8.8857422
-0.00094175339	0.00026244321	-0.00014624929	0	683.10748	0	9.0664063	9.0849609
-0.00016450882	-0.00051480136	-0.00024975961	0	681.38538	0	9.265625	9.2841797
-0.0012755394	0.00059622922	-0.00023506364	0	681.19714	0	9.4648438	9.4833984
-0.00063419342	-4.5116758e-05	-0.00019712606	0	683.75537	0	9.6640625	9.6826172
-0.00090837479	0.00022906461	8.4007115e-05	0	678.93005	0	9.8632813	9.8818359
-0.0014591217	0.0021795512	-6.6101711e-05	0	665.15656	0	10.0625	10.081055
0.0024366379	0.004924417	-0.00013652352	0	778.3233	0	10.261719	10.280273
0.010538101	0.0034635793	-6.9497764e-05	0	977.89746	0	10.460938	10.479492
0.016515255	0.0041270498	-6.3214611e-05	0	1142.5793	0	10.660156	10.678711
0.024211407	0.0030715242	-2.233719e-07	0	1355.1842	0	10.859375	10.87793
0.031344891	0.0025786646	4.6831701e-05	0	1565.1471	0	11.058594	11.077148
0.039916039	0.00064814463	0.00013529934	0	1797.0636	0	11.257813	11.276367
0.046360493	0.00084431469	3.6609345e-05	0	1999.2695	0	11.457031	11.475586
0.053613186	0.00023224577	0.00012612545	0	2207.4097	0	11.65625	11.674805
0.060589314	-0.0001032576	0.00012862838	0	2395.9941	0	11.855469	11.874023
0.066292286	0.00083439797	0.00020321568	0	2568.5757	0	12.054688	12.073242
0.071349144	0.0024181679	0.00027420538	0	2737.2825	0	12.253906	12.272461
0.078620911	0.0017870218	0.00035107441	0	2930.5425	0	12.453125	12.47168
0.086066723	0.00098183751	0.00048610527	0	3175.1758	0	12.652344	12.670898
0.093448162	0.00024101883	0.00043751241	0	3390.1646	0	12.851563	12.870117
0.099205971	0.0011238381	0.00035471603	0	3568.8594	0	13.050781	13.069336
0.10506868	0.0019017532	0.00040551642	0	3746.7368	0	13.25	13.268555
0.114007	-0.00039593875	0.00038199432	0	4009.2834	0	13.449219	13.467773
0.12063265	-0.00038096309	0.00057000655	0	4223.3955	0	13.648438	13.666992
0.12602329	0.00086902082	0.00057815015	0	4402.7813	0	13.847656	13.866211
0.13198853	0.001544416	0.00052400935	0	4564.8325	0	14.046875	14.06543
0.13921499	0.0009585619	0.00063143997	0	4800.6929	0	14.246094	14.264648
0.14567852	0.0011356622	0.00065467757	0	5012.6943	0	14.445313	14.463867
0.15237093	0.0010838807	0.00058362237	0	5207.2861	0	14.644531	14.663086
0.15944242	0.00065301359	0.00083452684	0	5407.1953	0	14.84375	14.862305
0.16553164	0.0012044311	0.00061159482	0	5611.2373	0	15.042969	15.061523
0.1726675	0.00070919096	0.00095937721	0	5812.3511	0	15.242188	15.260742
0.17846823	0.00154908	0.00094493665	0	5982.7881	0	15.441406	15.459961
0.18506765	0.0015902817	0.00090681534	0	6186.2593	0	15.640625	15.65918
0.19304037	0.00025819242	0.00091451767	0	6356.6123	0	15.839844	15.858398
0.20000696	-6.7770481e-05	0.0010124844	0	6535.3643	0	16.039063	16.057617
0.20544291	0.0011369139	0.00094884163	0	6690.8423	0	16.238281	16.256836
0.21170139	0.0015190542	0.0010563639	0	6882.2007	0	16.4375	16.456055
0.21929264	0.00056841969	0.00097692467	0	7050.127	0	16.636719	16.655273
0.2259469	0.00055478513	0.0011726418	0	7194.8862	0	16.835938	16.854492
0.23314476	-2.4437904e-06	0.0011015865	0	7334.8286	0	17.035156	17.053711
0.23834467	0.001438275	0.0012231143	0	7492.9141	0	17.234375	17.25293
0.2461195	0.0003040731	0.0012665191	0	7689.8608	0	17.433594	17.452148
0.25245905	0.00060513616	0.0012455683	0	7849.4932	0	17.632813	17.651367
0.25855541	0.001149416	0.0013623248	0	7997.165	0	17.832031	17.850586
0.26523113	0.0011143088	0.0012610438	0	8169.959	0	18.03125	18.049805
0.27258158	0.00040447712	0.001364555	0	8358.3184	0	18.230469	18.249023
0.27880192	0.00082477927	0.0013079989	0	8528.2305	0	18.429688	18.448242
0.28557301	0.0006943047	0.0013408503	0	8713.6514	0	18.628906	18.647461
0.29238939	0.00051856041	0.0013142963	0	8890.6582	0	18.828125	18.84668
0.29863834	0.00091022253	0.0013813584	0	9047.1035	0	19.027344	19.045898
0.305233	0.00095620751	0.001603489	0	9214.5723	0	19.226563	19.245117
0.31204224	0.00078758597	0.0015740064	0	9409.5449	0	19.425781	19.444336
0.31863928	0.00083115697	0.0016094894	0	9579.1514	0	19.625	19.643555
0.32534599	0.00076508522	0.0016120088	0	9741.3721	0	19.824219	19.842773
0.3311491	0.0016025901	0.0015377089	0	9907.4414	0	20.023438	20.041992
0.3400445	-0.00065216422	0.0016509516	0	10113.754	0	20.222656	20.241211
0.3458643	0.00016865134	0.0015560301	0	10285.055	0	20.421875	20.44043
0.35223246	0.00044110417	0.0016541522	0	10437.563	0	20.621094	20.639648
0.35747766	0.0018365383	0.0017030841	0	10599.149	0	20.820313	20.838867
0.36480904	0.0011457801	0.001657784	0	10777.293	0	21.019531	21.038086
0.37201881	0.00057664514	0.0017843569	0	10955.439	0	21.21875	21.237305
0.37847519	0.00076088309	0.0018712111	0	11121.529	0	21.417969	21.436523
0.38497925	0.00089743733	0.0016702135	0	11283.211	0	21.617188	21.635742
0.39237738	0.00013995171	0.0018074526	0	11448.184	0	21.816406	21.834961
0.39795637	0.00120157	0.0019027309	0	11615.647	0	22.015625	22.03418
0.40520191	0.0005966723	0.0019824812	0	11784.831	0	22.214844	22.233398
0.41263342	-0.00019422174	0.0019161216	0	11967.771	0	22.414063	22.432617
0.41810036	0.00097948313	0.0018827075	0	12136.97	0	22.613281	22.631836
0.42413712	0.0015833378	0.0021002551	0	12296.376	0	22.8125	22.831055
0.43123007	0.0011309981	0.0020243214	0	12448.106	0	23.011719	23.030273
0.43827057	0.00073114038	0.0019710213	0	12619.749	0	23.210938	23.229492
0.44595957	-0.00031724572	0.0020785155	0	12834.156	0	23.410156	23.428711
0.45276642	-0.00048345327	0.002066744	0	12997.203	0	23.609375	23.62793
0.45891762	5.9604645e-06	0.0023009279	0	13130.645	0	23.808594	23.827148
0.46460867	0.00095552206	0.0022822749	0	13270.825	0	24.007813	24.026367
0.47193289	0.00027194619	0.0023414842	0	13453.616	0	24.207031	24.225586
0.47868252	0.0001629293	0.002296858	0	13615.823	0	24.40625	24.424805
0.48475742	0.00072866678	0.0024456165	0	13767.773	0	24.605469	24.624023
0.49178123	0.00034546852	0.0022704441	0	13925.188	0	24.804688	24.823242
0.49831867	0.00044864416	0.0022933341	0	14096.724	0	25.003906	25.022461
0.50428867	0.001119256	0.0023186235	0	14260.319	0	25.203125	25.22168
0.51107407	0.00097453594	0.0024443022	0	14410.953	0	25.402344	25.420898
0.51763773	0.0010514855	0.0024218019	0	14573.333	0	25.601563	25.620117
0.52446127	0.00086855888	0.0024987881	0	14728.665	0	25.800781	25.819336
0.53055286	0.0014175773	0.0024639191	0	14878.693	0	26	26.018555
0.53776026	0.0008507967	0.0024381038	0	15064.525	0	26.199219	26.217773
0.54491997	0.00033175945	0.0023984839	0	15225.347	0	26.398438	26.416992
0.55050611	0.0013862252	0.0024920045	0	15367.965	0	26.597656	26.616211
0.55881023	-0.00027728081	0.0024175283	0	15557.498	0	26.796875	26.81543
0.56510448	6.9081783e-05	0.0025100005	0	15709.656	0	26.996094	27.014648
0.57082653	0.00098770857	0.0025001084	0	15846.855	0	27.195313	27.213867
0.57739735	0.0010575056	0.002571441	0	15989.074	0	27.394531	27.413086
0.58442354	0.00067192316	0.0026641062	0	16154.152	0	27.59375	27.612305
0.59158802	0.00014805794	0.0027968241	0	16307.123	0	27.792969	27.811523
0.59914351	-0.00076681376	0.0027191313	0	16474.814	0	27.992188	28.010742
0.60498953	2.7835369e-05	0.0028229274	0	16622.938	0	28.191406	28.209961
0.611341	0.0003169775	0.0027968469	0	16769.652	0	28.390625	28.40918
0.61808825	0.00021034479	0.0030116807	0	16926.789	0	28.589844	28.608398
0.62444448	0.00049471855	0.002904084	0	17078.623	0	28.789063	28.807617
0.63149691	8.2910061e-05	0.0030154174	0	17221.191	0	28.988281	29.006836
0.63817501	4.5478344e-05	0.0029959942	0	17372.775	0	29.1875	29.206055
0.64345121	0.0014098883	0.0030120783	0	17506.521	0	29.386719	29.405273
0.65059423	0.00090748072	0.0031230219	0	17669.336	0	29.585938	29.604492
0.65827608	-0.00013375282	0.0033360764	0	17859.686	0	29.785156	29.803711
0.66539526	-0.00061231852	0.0031070504	0	18001.072	0	29.984375	30.00293
0.67107201	0.0003516078	0.0032991134	0	18117.877	0	30.183594	30.202148
0.67710876	0.00095546246	0.0032069283	0	18240.053	0	30.382813	30.401367
0.68369865	0.001006186	0.0033288456	0	18398.543	0	30.582031	30.600586
0.69098711	0.00035834312	0.0032806457	0	18559.133	0	30.78125	30.799805
0.69766998	0.00031608343	0.0032440261	0	18691.676	0	30.980469	30.999023
0.70382118	0.00080555677	0.0033525045	0	18849.098	0	31.179688	31.198242
0.71112633	0.00014102459	0.0033131421	0	18997.521	0	31.378906	31.397461
0.71730614	0.0006018281	0.0035059839	0	19127.811	0	31.578125	31.59668
0.72328568	0.0012629032	0.0033599462	0	19262.574	0	31.777344	31.795898
0.72929382	0.0018953681	0.0034114956	0	19397.117	0	31.976563	31.995117
0.73734999	0.000479877	0.0033712392	0	19566.686	0	32.175781	32.194336
0.74472189	-0.00025141239	0.0035219386	0	19730.508	0	32.375	32.393555
0.75185299	-0.00074189901	0.0035271491	0	19869.994	0	32.574219	32.592773
0.75829268	-0.00054097176	0.0035224578	0	19991.227	0	32.773438	32.791992
0.76385975	0.0005325675	0.0035367515	0	20101.137	0	32.972656	32.991211
0.76953888	0.0014941096	0.0036732904	0	20228.537	0	33.171875	33.19043
0.77661514	0.0010584593	0.0037269916	0	20374.33	0	33.371094	33.389648
0.78352928	0.00078493357	0.0038662793	0	20517.076	0	33.570313	33.588867
0.78988791	0.0010669231	0.0036755961	0	20654.619	0	33.769531	33.788086
0.79663277	0.00096267462	0.0037283655	0	20787.863	0	33.96875	33.987305
0.803895	0.00034111738	0.0037811624	0	20940.084	0	34.167969	34.186523
0.81085682	1.9907951e-05	0.0037995297	0	21075.873	0	34.367188	34.385742
0.81652164	0.00099569559	0.0038223474	0	21200.143	0	34.566406	34.584961
0.82240105	0.0017569065	0.0039218413	0	21324.768	0	34.765625	34.78418
0.83092928	-0.00013065338	0.0039315536	0	21478.393	0	34.964844	34.983398
0.83767653	-0.00023728609	0.0037859874	0	21610.33	0	35.164063	35.182617
0.8441186	-3.8743019e-05	0.0039009715	0	21748.467	0	35.363281	35.381836
0.85053921	0.00018125772	0.0039279964	0	21886.416	0	35.5625	35.581055
0.8571887	0.00017237663	0.0039618681	0	22008.283	0	35.761719	35.780273
0.8633399	0.00066184998	0.0041444628	0	22128.875	0	35.960938	35.979492
0.87083101	-0.0001886487	0.0040053544	0	22276.127	0	36.160156	36.178711
0.87759256	-0.00030958652	0.0039931671	0	22404.92	0	36.359375	36.37793
0.88319063	0.00073295832	0.0040420527	0	22521.26	0	36.558594	36.577148
0.88896275	0.0016014576	0.0041307653	0	22636.91	0	36.757813	36.776367
0.89653254	0.00067234039	0.0041018263	0	22778.578	0	36.957031	36.975586
0.9031558	0.00068968534	0.0042524738	0	22907.934	0	37.15625	37.174805
0.9102726	0.00021350384	0.0043336404	0	23036.109	0	37.355469	37.374023
0.91710091	2.5808811e-05	0.004121345	0	23156.838	0	37.554688	37.573242
0.92387438	-0.00010704994	0.0042587519	0	23290.371	0	37.753906	37.772461
0.93039513	1.2874603e-05	0.0041939998	0	23427.424	0	37.953125	37.97168
0.93689442	0.00015419722	0.0043566623	0	23543.035	0	38.152344	38.170898
0.94328403	0.00040519238	0.0042762933	0	23654.66	0	38.351563	38.370117
0.9501195	0.00021034479	0.0043573296	0	23785.943	0	38.550781	38.569336
0.95696211	8.3446503e-06	0.0043418771	0	23923.516	0	38.75	38.768555
0.96406698	-0.00045585632	0.0043415232	0	24046.828	0	38.949219	38.967773
0.96955061	0.00070112944	0.0042656921	0	24150.295	0	39.148438	39.166992
0.97659826	0.00029408932	0.0042795734	0	24260.002	0	39.347656	39.366211
0.98209143	0.0014415383	0.0044320766	0	24385.404	0	39.546875	39.56543
0.99057913	-0.00040555	0.004542829	0	24537.037	0	39.746094	39.764648
0.99722147	-0.00040721893	0.0046146419	0	24648.814	0	39.945313	39.963867
1.0033178	0.00013697147	0.0046436042	0	24755.559	0	40.144531	40.163086
1.0097289	0.00036656857	0.0045592892	0	24856.154	0	40.34375	40.362305
1.0167074	2.8729439e-05	0.0046859412	0	24998.064	0	40.542969	40.561523
1.0227013	0.00067543983	0.0045903451	0	25115.473	0	40.742188	40.760742
1.0289836	0.001033783	0.004714861	0	25224.441	0	40.941406	40.959961
1.0359979	0.00066006184	0.0047541419	0	25339.246	0	41.140625	41.15918
1.0431671	0.00013148785	0.0046578501	0	25466.578	0	41.339844	41.358398
1.0497141	0.00022518635	0.0047347606	0	25578.699	0	41.539063	41.557617
1.0559487	0.00063109398	0.0047529824	0	25696.563	0	41.738281	41.756836
1.0631156	0.00010490417	0.0047813738	0	25819.879	0	41.9375	41.956055
1.0695839	0.0002771616	0.0048292219	0	25927.293	0	42.136719	42.155273
1.0756993	0.00080239773	0.0048125922	0	26024.621	0	42.335938	42.354492
1.0830164	0.00012600422	0.0050027566	0	26179.504	0	42.535156	42.553711
1.0908985	-0.0011155605	0.0047477172	0	26296.234	0	42.734375	42.75293
1.0973048	-0.00088119507	0.0050254455	0	26393.371	0	42.933594	42.952148
1.1024237	0.00064051151	0.0047961576	0	26479.381	0	43.132813	43.151367
1.1089587	0.00074613094	0.0048966026	0	26575.932	0	43.332031	43.350586
1.1152172	0.0011283159	0.0048903669	0	26708.852	0	43.53125	43.549805
1.1235452	-0.00055909157	0.0049064374	0	26835.357	0	43.730469	43.749023
1.129725	-9.8228455e-05	0.0048673525	0	26927.465	0	43.929688	43.948242
1.1355329	0.00073444843	0.0049839905	0	27027.172	0	44.128906	44.147461
1.1416292	0.001278758	0.0049857711	0	27132.273	0	44.328125	44.34668
1.1496449	-9.6201897e-05	0.0050179083	0	27262.373	0	44.527344	44.545898
1.1564302	-0.00024104118	0.0050167195	0	27373.355	0	44.726563	44.745117
1.1627698	6.0081482e-05	0.0051235091	0	27469.273	0	44.925781	44.944336
1.1685157	0.00095486641	0.0051616016	0	27566.861	0	45.125	45.143555
1.1752582	0.00085294247	0.0050772075	0	27678.801	0	45.324219	45.342773
1.1828828	-0.00013101101	0.0049648015	0	27808.861	0	45.523438	45.541992
1.189816	-0.00042366982	0.0050674775	0	27915.674	0	45.722656	45.741211
1.1951971	0.00083589554	0.0050700316	0	28003.633	0	45.921875	45.94043
1.2025309	0.00014281273	0.0050226748	0	28098.912	0	46.121094	46.139648
1.2086344	0.00067985058	0.0050303107	0	28204.365	0	46.320313	46.338867
1.2157345	0.00022041798	0.0050493227	0	28310.098	0	46.519531	46.538086
1.2218142	0.00078129768	0.0051038135	0	28408.648	0	46.71875	46.737305
1.2292528	-1.6689301e-05	0.005271324	0	28514.225	0	46.917969	46.936523
1.2358499	2.6941299e-05	0.0053397384	0	28636.521	0	47.117188	47.135742
1.2434101	-0.00089275837	0.0052698744	0	28734.205	0	47.316406	47.334961
1.2491298	2.8252602e-05	0.0051780604	0	28817.117	0	47.515625	47.53418
1.2551117	0.00068688393	0.0052710446	0	28896.236	0	47.714844	47.733398
1.2611604	0.0012788773	0.0053553628	0	28985.23	0	47.914063	47.932617
1.2685776	0.00050234795	0.0052558491	0	29110.398	0	48.113281	48.131836
1.2767959	-0.001075387	0.0053623538	0	29236.502	0	48.3125	48.331055
1.2824798	-0.00011861324	0.0052564079	0	29325.023	0	48.511719	48.530273
1.2876058	0.0013959408	0.0052664769	0	29403.48	0	48.710938	48.729492
1.2953639	0.0002784729	0.005364201	0	29483.563	0	48.910156	48.928711
1.3010955	0.0011875629	0.0053800037	0	29581.473	0	49.109375	49.12793
1.3079453	0.00097835064	0.0053660339	0	29688.77	0	49.308594	49.327148
1.3160062	-0.00044190884	0.0053866296	0	29791.297	0	49.507813	49.526367
1.321733	0.00047183037	0.005462206	0	29872.994	0	49.707031	49.725586
1.3288617	-1.6212463e-05	0.0054540797	0	29972.801	0	49.90625	49.924805
1.3348818	0.0006043911	0.0054110941	0	30073.301	0	50.105469	50.124023
1.3420391	8.7618828e-05	0.0053689349	0	30156.734	0	50.304688	50.323242
1.3484144	0.00035297871	0.0054127239	0	30240.957	0	50.503906	50.522461
1.3551426	0.00026535988	0.005461324	0	30338.709	0	50.703125	50.72168
1.3616681	0.00038051605	0.00548077	0	30438.93	0	50.902344	50.920898
1.3686109	7.8439713e-05	0.0055926275	0	30529.139	0	51.101563	51.120117
1.3751459	0.00018393993	0.0055013006	0	30604.756	0	51.300781	51.319336
1.3817	0.00027048588	0.0054439823	0	30698.762	0	51.5	51.518555
1.3887072	-9.6082687e-05	0.0056089913	0	30807.426	0	51.699219	51.717773
1.3948035	0.00044822693	0.0055874474	0	30895.879	0	51.898438	51.916992
1.4016795	0.00021290779	0.0055871126	0	30971.568	0	52.097656	52.116211
1.4077783	0.00075471401	0.0056137145	0	31051.02	0	52.296875	52.31543
1.4151931	-1.9431114e-05	0.0056419931	0	31167.23	0	52.496094	52.514648
1.422236	-0.00042176247	0.0056556137	0	31251.381	0	52.695313	52.713867
1.4279461	0.00050878525	0.0056783687	0	31326.682	0	52.894531	52.913086
1.4350033	9.226799e-05	0.0056897192	0	31399.959	0	53.09375	53.112305
1.4411688	0.00056731701	0.0057724039	0	31489.148	0	53.292969	53.311523
1.4481497	0.0002270937	0.0057264101	0	31581.461	0	53.492188	53.510742
1.4552021	-0.0001847744	0.0056711892	0	31659.541	0	53.691406	53.709961
1.4606714	0.00098657608	0.0059141233	0	31731.445	0	53.890625	53.90918
1.4678097	0.00048899651	0.0059463144	0	31830.713	0	54.089844	54.108398
1.4753938	-0.00045454502	0.0058441148	0	31926.039	0	54.289063	54.307617
1.4816451	-6.5207481e-05	0.0059124674	0	32008.797	0	54.488281	54.506836
1.4881158	0.00010466576	0.0058754156	0	32083.396	0	54.6875	54.706055
1.4935255	0.0013356209	0.0059177633	0	32157.047	0	54.886719	54.905273
1.500721	0.00078082085	0.0058815326	0	32236.133	0	55.085938	55.104492
1.5085602	-0.00041782856	0.0057714274	0	32336.385	0	55.285156	55.303711
1.5154123	-0.00062930584	0.0058376631	0	32426.148	0	55.484375	55.50293
1.5213299	9.3698502e-05	0.0059114415	0	32499.256	0	55.683594	55.702148
1.5284681	-0.00040388107	0.0058273794	0	32570.828	0	55.882813	55.901367
1.5342355	0.00046944618	0.0059595564	0	32637.168	0	56.082031	56.100586
1.541369	-2.348423e-05	0.0059066736	0	32727.482	0	56.28125	56.299805
1.5486908	-0.00070464611	0.005970811	0	32841.66	0	56.480469	56.499023
1.5548062	-0.00017952919	0.0059184567	0	32917.75	0	56.679688	56.698242
1.5613008	-3.3378601e-05	0.0059226402	0	32977.863	0	56.878906	56.897461
1.56744	0.00046801567	0.0060489005	0	33031.746	0	57.078125	57.09668
1.5731907	0.001357913	0.0059955032	0	33105.629	0	57.277344	57.295898
1.5800524	0.001136899	0.0059837233	0	33193.551	0	57.476563	57.495117
1.5874076	0.0004222393	0.0059864121	0	33280.547	0	57.675781	57.694336
1.5941715	0.0002989769	0.0061060716	0	33353.199	0	57.875	57.893555
1.6002011	0.00091004372	0.0060387552	0	33418.566	0	58.074219	58.092773
1.6068602	0.00089156628	0.0059430124	0	33494.672	0	58.273438	58.291992
1.6144633	-7.0929527e-05	0.0061788158	0	33578.43	0	58.472656	58.491211
1.6214085	-0.00037539005	0.006108541	0	33655.582	0	58.671875	58.69043
1.6276383	3.528595e-05	0.0060303994	0	33728.859	0	58.871094	58.889648
1.6332459	0.0010683537	0.0059107724	0	33796.074	0	59.070313	59.088867
1.6401911	0.00076377392	0.0061184759	0	33865.902	0	59.269531	59.288086
1.6472006	0.00039494038	0.006091259	0	33946.176	0	59.46875	59.487305
1.6538095	0.00042665005	0.0061031268	0	34027.914	0	59.667969	59.686523
1.6605234	0.00035333633	0.0061376989	0	34098.598	0	59.867188	59.885742
1.667273	0.00024437904	0.0061587961	0	34158.184	0	60.066406	60.084961
1.6734672	0.00069081783	0.0062055178	0	34228.715	0	60.265625	60.28418
1.6806102	0.00018846989	0.0061106728	0	34301.125	0	60.464844	60.483398
1.6877842	-0.00034487247	0.0061344872	0	34384.211	0	60.664063	60.682617
1.6946745	-0.00059461594	0.0060574831	0	34457.609	0	60.863281	60.881836
1.7002869	0.0004336834	0.0061633969	0	34522.703	0	61.0625	61.081055
1.7066836	0.00067746639	0.0062501687	0	34580.875	0	61.261719	61.280273
1.7136788	0.00032293797	0.0060390448	0	34658.742	0	61.460938	61.479492
1.7199111	0.00073134899	0.0060588256	0	34731.125	0	61.660156	61.678711
1.7268682	0.00041484833	0.0062252828	0	34796.895	0	61.859375	61.87793
1.7330933	0.00083041191	0.0062486259	0	34857.688	0	62.058594	62.077148
1.7400026	0.00056159496	0.0062892293	0	34931.914	0	62.257813	62.276367
1.7469335	0.00027143955	0.0063463249	0	35003.453	0	62.457031	62.475586
1.7540884	-0.00024282932	0.0061743557	0	35071.469	0	62.65625	62.674805
1.7602777	0.00020837784	0.0063861888	0	35133.598	0	62.855469	62.874023
1.7669296	0.00019717216	0.0063355896	0	35197.73	0	63.054688	63.073242
1.7740297	-0.00026237965	0.0063273245	0	35261.496	0	63.253906	63.272461
1.7806864	-0.00027835369	0.0063469494	0	35340.676	0	63.453125	63.47168
1.7883468	-0.00129807	0.0063780886	0	35413.25	0	63.652344	63.670898
1.7942858	-0.00059652328	0.0063217464	0	35470.566	0	63.851563	63.870117
1.8005157	-0.00018572807	0.0062419209	0	35516.039	0	64.050781	64.069336
1.8072319	-0.00026142597	0.0063100015	0	35580.621	0	64.25	64.268555
1.813004	0.00060713291	0.0063224789	0	35638.219	0	64.449219	64.467773
1.8204117	-0.00015985966	0.0064932485	0	35701.32	0	64.648438	64.666992
1.8269038	-1.1444092e-05	0.0062285755	0	35772.195	0	64.847656	64.866211
1.8331957	0.00033736229	0.0063681635	0	35835.738	0	65.046875	65.06543
1.8393588	0.00081479549	0.0062797987	0	35895.285	0	65.246094	65.264648
1.8472171	-0.00040280819	0.0064437478	0	35964.762	0	65.445313	65.463867
1.8532395	0.00021541119	0.0063981856	0	36030.566	0	65.644531	65.663086
1.8594313	0.00066423416	0.0064378055	0	36096.066	0	65.84375	65.862305
1.8662691	0.000467062	0.0063507687	0	36162.328	0	66.042969	66.061523
1.8728614	0.00051534176	0.0064878929	0	36222.016	0	66.242188	66.260742
1.8801379	-0.00012052059	0.0063378797	0	36290.824	0	66.441406	66.459961
1.8863392	0.00031888485	0.0063188914	0	36349.32	0	66.640625	66.65918
1.8932509	4.7683716e-05	0.0064848303	0	36413.727	0	66.839844	66.858398
1.8994927	0.000446558	0.0065400065	0	36464.055	0	67.039063	67.057617
1.9053578	0.0012220144	0.006635197	0	36524.063	0	67.238281	67.256836
1.9133353	-0.00011479855	0.0065966994	0	36601.449	0	67.4375	67.456055
1.9200206	-0.00015938282	0.0065582292	0	36676.023	0	67.636719	67.655273
1.9259429	0.00055885315	0.0066480278	0	36732.766	0	67.835938	67.854492
1.9324756	0.00066685677	0.0065792324	0	36786.973	0	68.035156	68.053711
1.9391704	0.00061261654	0.0066136876	0	36842.363	0	68.234375	68.25293
1.9459105	0.00051319599	0.0065260595	0	36903.16	0	68.433594	68.452148
1.9538617	-0.00079739094	0.0065953359	0	36979.016	0	68.632813	68.651367
1.9597411	-3.6239624e-05	0.0065438864	0	37034.66	0	68.832031	68.850586
1.9658065	0.00053906441	0.0066098771	0	37090.523	0	69.03125	69.049805
1.9727135	0.00027263165	0.0065842117	0	37142.027	0	69.230469	69.249023
1.9788742	0.00075256824	0.0065921624	0	37201.109	0	69.429688	69.448242
1.9855118	0.00075566769	0.0066612973	0	37261.82	0	69.628906	69.647461
1.9926214	0.00028657913	0.0064971098	0	37335.094	0	69.828125	69.84668
1.999023	0.00052571297	0.0065448536	0	37393.254	0	70.027344	70.045898
2.0056295	0.00055980682	0.0066620633	0	37453.605	0	70.226563	70.245117
2.0128131	1.6927719e-05	0.0065768659	0	37512.676	0	70.425781	70.444336
2.0195603	-8.9883804e-05	0.0067312866	0	37573.688	0	70.625	70.643555
2.0263815	-0.00027036667	0.006722854	0	37628.859	0	70.824219	70.842773
2.0325732	0.00017857552	0.0067651002	0	37681.527	0	71.023438	71.041992
2.0394588	-6.6280365e-05	0.0067060944	0	37728.055	0	71.222656	71.241211
2.0455956	0.00043749809	0.0067278012	0	37794.52	0	71.421875	71.44043
2.0521593	0.00051426888	0.0066066845	0	37859.258	0	71.621094	71.639648
2.0594072	-9.2983246e-05	0.0065628989	0	37914.422	0	71.820313	71.838867
2.065835	0.00011992455	0.0067968755	0	37961.891	0	72.019531	72.038086
2.0717454	0.00085020065	0.0068091713	0	38014.844	0	72.21875	72.237305
2.0785475	0.00068879128	0.0068660066	0	38073.129	0	72.417969	72.436523
2.0855045	0.0003721714	0.0067912587	0	38131.617	0	72.617188	72.635742
2.0923376	0.00017976761	0.0069062589	0	38182.547	0	72.816406	72.834961
2.0991969	-3.8862228e-05	0.006942675	0	38242.828	0	73.015625	73.03418
2.1057343	6.4373016e-05	0.0068765283	0	38300.777	0	73.214844	73.233398
2.1115589	0.00088047981	0.0067493338	0	38357.875	0	73.414063	73.432617
2.1183991	0.00068068504	0.0069209184	0	38417.391	0	73.613281	73.631836
2.1264124	-0.00069189072	0.0067405775	0	38465.164	0	73.8125	73.831055
2.1317887	0.00057244301	0.0067693805	0	38512.145	0	74.011719	74.030273
2.1387887	0.00021314621	0.0068981387	0	38564.379	0	74.210938	74.229492
2.1451735	0.00046896935	0.0069854204	0	38633.426	0	74.410156	74.428711
2.1527457	-0.00046277046	0.0070963339	0	38697.895	0	74.609375	74.62793
2.1590018	-7.8201294e-05	0.0070058205	0	38743.109	0	74.808594	74.827148
2.1650195	0.00054478645	0.0069039571	0	38788.344	0	75.007813	75.026367
2.1720552	0.00014972687	0.0069091003	0	38836.305	0	75.207031	75.225586
2.1792006	-0.00035500526	0.0069707455	0	38895.902	0	75.40625	75.424805
2.1849179	0.00056815147	0.0069680028	0	38949.023	0	75.605469	75.624023
2.1915174	0.00060939789	0.0069510653	0	38996.699	0	75.804688	75.823242
2.1973825	0.0013849735	0.0070662978	0	39043.789	0	76.003906	76.022461
2.2052598	0.00014829636	0.007148983	0	39099.152	0	76.203125	76.22168
2.2117329	0.00031590462	0.0069872509	0	39153.809	0	76.402344	76.420898
2.2182918	0.00039744377	0.0070571485	0	39208.801	0	76.601563	76.620117
2.2250605	0.00026941299	0.0071443305	0	39262.512	0	76.800781	76.819336
2.231009	0.00096154213	0.0071233269	0	39315.09	0	77	77.018555
2.2388434	-0.0002322197	0.0071768593	0	39372.926	0	77.199219	77.217773
2.2457576	-0.00050568581	0.0071299677	0	39422.598	0	77.398438	77.416992
2.252748	-0.00085568428	0.0071243835	0	39476.852	0	77.597656	77.616211
2.2589588	-0.00042581558	0.0069452976	0	39527.25	0	77.796875	77.81543
2.2647381	0.00043559074	0.007208148	0	39573.172	0	77.996094	78.014648
2.2717571	5.7220459e-05	0.0072426992	0	39629.984	0	78.195313	78.213867
2.2785878	-0.00013279915	0.0070922202	0	39689.805	0	78.394531	78.413086
2.284925	0.00017046928	0.0071542277	0	39744.777	0	78.59375	78.612305
2.2919655	-0.00022935867	0.0073258174	0	39789.742	0	78.792969	78.811523
2.2977924	0.00058436394	0.0071812775	0	39834.914	0	78.992188	79.010742
2.3040152	0.0010023117	0.0071166498	0	39877.457	0	79.191406	79.209961
2.3113537	0.00030446053	0.0072262385	0	39940.918	0	79.390625	79.40918
2.317965	0.00033354759	0.0070864414	0	39996.621	0	79.589844	79.608398
2.3243165	0.00062274933	0.0073228925	0	40045.082	0	79.789063	79.807617
2.3312378	0.00034213066	0.0071471268	0	40092.863	0	79.988281	80.006836
2.3379946	0.00022602081	0.0072123609	0	40144.484	0	80.1875	80.206055
2.3453116	-0.0004503727	0.0073153484	0	40211.5	0	80.386719	80.405273
2.3521638	-0.00066208839	0.0072393878	0	40260.383	0	80.585938	80.604492
2.358191	-4.863739e-05	0.0073391567	0	40301.629	0	80.785156	80.803711
2.3648834	-0.00010037422	0.0073564467	0	40344.465	0	80.984375	81.00293
2.3706365	0.00078725815	0.0072800331	0	40382.629	0	81.183594	81.202148
2.3774767	0.0005877018	0.0074332245	0	40425.496	0	81.382813	81.401367
2.3846626	4.2200089e-05	0.0073032202	0	40482.816	0	81.582031	81.600586
2.3911572	0.00018835068	0.007288523	0	40538.156	0	81.78125	81.799805
2.3975825	0.00040364265	0.007390596	0	40582.59	0	81.980469	81.999023
2.4048829	-0.00025606155	0.0074942377	0	40648.895	0	82.179688	82.198242
2.4118805	-0.00061297417	0.0074570756	0	40696.93	0	82.378906	82.397461
2.4176335	0.00027441978	0.0073813573	0	40737.531	0	82.578125	82.59668
2.4235201	0.0010285378	0.0075049675	0	40771.43	0	82.777344	82.795898
2.4315619	-0.00037264824	0.0073889471	0	40831.086	0	82.976563	82.995117
2.4380445	-0.00021457672	0.0073988126	0	40881.172	0	83.175781	83.194336
2.4444556	1.502037e-05	0.007560031	0	40928.508	0	83.375	83.393555
2.4508429	0.0002682209	0.0074708029	0	40967.18	0	83.574219	83.592773
2.4572873	0.00046443939	0.0074398401	0	41003.465	0	83.773438	83.791992
2.4638772	0.00051522255	0.0074729072	0	41037.309	0	83.972656	83.991211
2.4703765	0.00065660477	0.007607332	0	41088.234	0	84.171875	84.19043
2.4774122	0.00026154518	0.0075171934	0	41159.656	0	84.371094	84.389648
2.4852681	-0.00095391273	0.0074938051	0	41231.031	0	84.570313	84.588867
2.4925447	-0.0015897751	0.0075504929	0	41287.605	0	84.769531	84.788086
2.4990201	-0.001424551	0.0074510574	0	41321.449	0	84.96875	84.987305
2.5052094	-0.00097322464	0.0074586198	0	41344.773	0	85.167969	85.186523
2.5107551	0.00012183189	0.0075749191	0	41373.73	0	85.367188	85.385742
2.5159764	0.0015408993	0.0076808622	0	41406.152	0	85.566406	85.584961
2.5232053	0.00095272064	0.0073736962	0	41457.34	0	85.765625	85.78418
2.5306654	0.00013327599	0.0073969574	0	41524.242	0	85.964844	85.983398
2.5379539	-0.00051450729	0.0075201006	0	41574.172	0	86.164063	86.182617
2.5434136	0.00066637993	0.0075728744	0	41617.688	0	86.363281	86.381836
2.5503516	0.00036883354	0.0074712858	0	41650.844	0	86.5625	86.581055
2.556572	0.0007891655	0.0074797487	0	41688.559	0	86.761719	86.780273
2.5640631	-6.1273575e-05	0.0074776048	0	41730.008	0	86.960938	86.979492
2.5706887	-4.6253204e-05	0.0073833419	0	41790.617	0	87.160156	87.178711
2.5775981	-0.00031495094	0.0075440654	0	41843.574	0	87.359375	87.37793
2.5845098	-0.00058627129	0.0075028869	0	41886.953	0	87.558594	87.577148
2.590692	-0.00012779236	0.0074851341	0	41919.66	0	87.757813	87.776367
2.5967383	0.00046658516	0.0076231798	0	41953.598	0	87.957031	87.975586
2.6027894	0.0010561943	0.0076431842	0	41995.449	0	88.15625	88.174805
2.6100588	0.00042748451	0.0076165558	0	42052.598	0	88.355469	88.374023
2.6167035	0.00042319298	0.0078006103	0	42115.961	0	88.554688	88.573242
2.6253271	-0.0015597343	0.0076033878	0	42165.961	0	88.753906	88.772461
2.631402	-0.00099396706	0.007723487	0	42204.199	0	88.953125	88.97168
2.6374316	-0.00038290024	0.0077067371	0	42238.688	0	89.152344	89.170898
2.6433372	0.00035214424	0.007456142	0	42269.402	0	89.351563	89.370117
2.6498795	0.0004503727	0.0075915107	0	42307.52	0	89.550781	89.569336
2.6563716	0.00059890747	0.0076828501	0	42354.176	0	89.75	89.768555
2.6640534	-0.00044226646	0.0077262735	0	42415.078	0	89.949219	89.967773
2.67061	-0.00035810471	0.0076811323	0	42468.211	0	90.148438	90.166992
2.676847	4.5537949e-05	0.0077333273	0	42512.285	0	90.347656	90.366211
2.6841974	-0.00066447258	0.0078080986	0	42546.84	0	90.546875	90.56543
2.6902843	-0.00011062622	0.0076304073	0	42583.219	0	90.746094	90.764648
2.6958299	0.00098443031	0.0079681845	0	42614.73	0	90.945313	90.963867
2.7031422	0.00031280518	0.0077070636	0	42656.598	0	91.144531	91.163086
2.7090025	0.0010931492	0.0076835649	0	42708.766	0	91.34375	91.362305
2.7166796	5.6505203e-05	0.0077907122	0	42762.703	0	91.542969	91.561523
2.7235436	-0.00016689301	0.0077956007	0	42810.195	0	91.742188	91.760742
2.7301335	-0.00011610985	0.0077133356	0	42847.016	0	91.941406	91.959961
2.7369952	-0.00033712387	0.0076923375	0	42883.254	0	92.140625	92.15918
2.743268	3.0755997e-05	0.0078049037	0	42925.168	0	92.339844	92.358398
2.7494478	0.00049161911	0.0078425296	0	42965.27	0	92.539063	92.557617
2.7568245	-0.00024461746	0.0077939732	0	43017.301	0	92.738281	92.756836
2.7640939	-0.00087332726	0.0078217164	0	43063.539	0	92.9375	92.956055
2.7706265	-0.00076532364	0.0078493785	0	43104.25	0	93.136719	93.155273
2.7774286	-0.00092673302	0.0077815345	0	43140.984	0	93.335938	93.354492
2.7838016	-0.00065898895	0.0077958824	0	43174.273	0	93.535156	93.553711
2.789309	0.00047397614	0.0078549897	0	43204.617	0	93.734375	93.75293
2.7960062	0.00041747093	0.0077824942	0	43237.809	0	93.933594	93.952148
2.8018618	0.0012025833	0.0078925509	0	43272.73	0	94.132813	94.151367
2.8086138	0.0010912418	0.0080098175	0	43320.781	0	94.332031	94.350586
2.8165865	-0.00024080276	0.0078926766	0	43372.164	0	94.53125	94.549805
2.8222132	0.00077295303	0.0079872021	0	43407.113	0	94.730469	94.749023
2.8298092	-0.00018239021	0.0077224658	0	43450.223	0	94.929688	94.948242
2.8359342	0.00033330917	0.0079630055	0	43479.563	0	95.128906	95.147461
2.8423882	0.00051999092	0.0079549244	0	43518.895	0	95.328125	95.34668
2.8489518	0.00059700012	0.0078591798	0	43558.59	0	95.527344	95.545898
2.856729	-0.00053977966	0.007860492	0	43604.422	0	95.726563	95.745117
2.863276	-0.00044608116	0.007700345	0	43640.074	0	95.925781	95.944336
2.8701544	-0.00068378448	0.0077717993	0	43666.152	0	96.125	96.143555
2.8759885	0.00012278557	0.0078462996	0	43687.523	0	96.324219	96.342773
2.8831434	-0.00039148331	0.0077599799	0	43722.168	0	96.523438	96.541992
2.8893709	2.1457672e-05	0.0078779329	0	43753.137	0	96.722656	96.741211
2.895484	0.00054907799	0.0078615407	0	43794.422	0	96.921875	96.94043
2.9028726	-0.00019884109	0.0078647472	0	43826.684	0	97.121094	97.139648
2.9088593	0.00045514107	0.0079090754	0	43852.707	0	97.320313	97.338867
2.91502	0.00093507767	0.0078916093	0	43875.516	0	97.519531	97.538086
2.9214334	0.0011620522	0.0079396209	0	43912.938	0	97.71875	97.737305
2.929492	-0.00025582314	0.0078980951	0	43952.23	0	97.917969	97.936523
2.9362655	-0.00038862228	0.0079675848	0	43992.789	0	98.117188	98.135742
2.9426122	-9.4652176e-05	0.0079433797	0	44022.391	0	98.316406	98.334961
2.9491282	3.0040741e-05	0.007831159	0	44046.574	0	98.515625	98.53418
2.9556584	0.00014019012	0.0078287236	0	44068.988	0	98.714844	98.733398
2.9614258	0.0010135174	0.0077952645	0	44088.25	0	98.914063	98.932617
2.9677415	0.0013384819	0.0077417688	0	44117.516	0	99.113281	99.131836
2.9751158	0.00060486794	0.0078059165	0	44145.898	0	99.3125	99.331055
2.9825377	-0.00017642975	0.0078718225	0	44185.301	0	99.511719	99.530273
2.9891849	-0.00018310547	0.0080561163	0	44215.715	0	99.710938	99.729492
2.9963636	-0.0007212162	0.0080117499	0	44237.23	0	99.910156	99.928711
3.0025434	-0.00026035309	0.0080666477	0	44256.559	0	100.10938	100.12793
3.0090475	-0.00012373924	0.0080580199	0	44274.215	0	100.30859	100.32715
3.0151772	0.00038719177	0.0080114445	0	44287.023	0	100.50781	100.52637
3.0219626	0.00024223328	0.0079045128	0	44301.18	0	100.70703	100.72559
3.0281925	0.00065302849	0.0082502738	0	44315.75	0	100.90625	100.9248
3.0356765	-0.00019025803	0.0079545593	0	44338.18	0	101.10547	101.12402
3.0423141	-0.00018715858	0.008084151	0	44359.516	0	101.30469	101.32324
3.0483985	0.00036907196	0.0079911519	0	44376.297	0	101.50391	101.52246
3.0549836	0.00042438507	0.0082218302	0	44390.055	0	101.70313	101.72168
3.0621505	-0.00010180473	0.007989753	0	44405.918	0	101.90234	101.9209
3.0653739	-4.7683716e-06	0.0080709616	0	44411.898	0	102.00195	102.02051

Data Acquisition						Time:	116.44238	s	12/20/2016 1:19:20 PM
Axial Displacement	Axial Displacement Error	Axial Extensometer	Axial Extensometer Abs. Error	Axial Force	Axial Force Abs. Error	Running Time	Time
mm	mm	mm/mm	mm/mm	N	N	s	s
3.0685735	0.00011587143	0.0080250427	0	44421.914	0	102.10156	102.12012
3.0717826	0.00022697449	0.0079495311	0	44427.688	0	102.20117	102.21973
3.075211	0.00011897087	0.0081024729	0	44437.465	0	102.30078	102.31934
3.0785966	5.364418e-05	0.0080201952	0	44441.5	0	102.40039	102.41895
3.0818152	0.00015544891	0.007945478	0	44445.75	0	102.5	102.51855
3.0852866	4.2915344e-06	0.0079688868	0	44451.512	0	102.59961	102.61816
3.0887628	-0.00015163422	0.0080764955	0	44453.766	0	102.69922	102.71777
3.0911827	0.00074887276	0.0081264963	0	44453.848	0	102.79883	102.81738
3.0961514	-0.0008995533	0.0079380181	0	44455.344	0	102.89844	102.91699
3.0990505	-0.00047826767	0.0080228569	0	44457.684	0	102.99805	103.0166
3.1024265	-0.00053405762	0.0078555262	0	44454.324	0	103.09766	103.11621
3.1047368	0.00047588348	0.0079996642	0	44453.914	0	103.19727	103.21582
3.1095076	-0.00097441673	0.0079353927	0	44456.887	0	103.29688	103.31543
3.1115389	0.00031447411	0.008112344	0	44460.102	0	103.39648	103.41504
3.1152272	-5.3405762e-05	0.0077877189	0	44457.836	0	103.49609	103.51465
3.1188369	-0.00034284592	0.0079519255	0	44457.66	0	103.5957	103.61426
3.1221747	-0.00036048889	0.0080694333	0	44457.922	0	103.69531	103.71387
3.125155	-2.0265579e-05	0.0079651773	0	44456.773	0	103.79492	103.81348
3.1293535	-0.00089859962	0.007864411	0	44453.645	0	103.89453	103.91309
3.1323838	-0.00060844421	0.0079894336	0	44451.969	0	103.99414	104.0127
3.1355238	-0.00042819977	0.0079722023	0	44450.672	0	104.09375	104.1123
3.1388855	-0.0004696846	0.0080473358	0	44448.344	0	104.19336	104.21191
3.1414676	0.00026869774	0.0080309361	0	44445.227	0	104.29297	104.31152
3.1454349	-0.00037837029	0.0080151809	0	44440.582	0	104.39258	104.41113
3.1486654	-0.00028848648	0.0079123853	0	44441.063	0	104.49219	104.51074
3.1518817	-0.00018453598	0.0080091581	0	44434.867	0	104.5918	104.61035
3.1559515	-0.00093412399	0.0079482822	0	44426.117	0	104.69141	104.70996
3.1592631	-0.00092530251	0.0078712935	0	44421.074	0	104.79102	104.80957
3.1628895	-0.001231432	0.007893973	0	44410.398	0	104.89063	104.90918
3.1664777	-0.001499176	0.0079908939	0	44381.285	0	104.99023	105.00879
3.169744	-0.0014452934	0.0079048388	0	44355.387	0	105.08984	105.1084
3.1732249	-0.0016059875	0.0079198405	0	44313.941	0	105.18945	105.20801
3.1764388	-0.0014994144	0.0079069659	0	44268.164	0	105.28906	105.30762
3.181119	-0.002859354	0.0079909451	0	44219.203	0	105.38867	105.40723
3.1852865	-0.0037064552	0.007972328	0	44161.656	0	105.48828	105.50684
3.1880713	-0.0031709671	0.0079484461	0	44106.473	0	105.58789	105.60645
3.1923151	-0.0040946007	0.0078327842	0	44051.465	0	105.6875	105.70605
3.195858	-0.0043170452	0.0079058371	0	43985.184	0	105.78711	105.80566
3.1988811	-0.0040199757	0.0079896431	0	43893.051	0	105.88672	105.90527
3.2016563	-0.0034747124	0.0078871921	0	43806.41	0	105.98633	106.00488
3.2052279	-0.0037260056	0.0078059821	0	43723.488	0	106.08594	106.10449
3.2090902	-0.0042681694	0.0080225784	0	43555.379	0	106.18555	106.2041
3.2124591	-0.0043165684	0.0077362969	0	43311.309	0	106.28516	106.30371
3.2193637	-0.0079009533	0.0076550548	0	42697.457	0	106.38477	106.40332
3.2233787	-0.010906696	-0.01041445	0	18841.986	0	106.48438	106.50293
3.2225013	-0.010029316	-0.010071181	0	19112.307	0	106.58398	106.60254
3.2228637	-0.010391712	-0.0099869315	0	19191.068	0	106.68359	106.70215
3.2208991	-0.0084271431	-0.0099046333	0	19200.611	0	106.7832	106.80176
3.2207274	-0.0082554817	-0.01008641	0	19237.088	0	106.88281	106.90137
3.2200003	-0.0075283051	-0.0099263694	0	19254.732	0	106.98242	107.00098
3.2196355	-0.0071635246	-0.0099294567	0	19265.416	0	107.08203	107.10059
3.2190847	-0.0066127777	-0.010147576	0	19278.572	0	107.18164	107.2002
3.2183671	-0.0058951378	-0.01005464	0	19278.877	0	107.28125	107.2998
3.217485	-0.005012989	-0.010057384	0	19298.582	0	107.38086	107.39941
3.2172942	-0.0048222542	-0.010029743	0	19290.096	0	107.48047	107.49902
3.2170892	-0.0046172142	-0.009975235	0	19302.445	0	107.58008	107.59863
3.2161617	-0.0036897659	-0.0099804541	0	19305.984	0	107.67969	107.69824
3.2162499	-0.0037779808	-0.010014227	0	19321.059	0	107.7793	107.79785
3.215766	-0.0032939911	-0.0099347057	0	19339.119	0	107.87891	107.89746
3.2148123	-0.0023403168	-0.0099665979	0	19343.588	0	107.97852	107.99707
3.2152128	-0.00274086	-0.010035642	0	19350.242	0	108.07813	108.09668
3.2146025	-0.0021305084	-0.0099470057	0	19356.977	0	108.17773	108.19629
3.2145739	-0.0021018982	-0.010043344	0	19366.201	0	108.27734	108.2959
3.2146811	-0.0022091866	-0.010019536	0	19369.012	0	108.37695	108.39551
3.2134795	-0.0010075569	-0.010134853	0	19341.291	0	108.47656	108.49512
3.2128119	-0.00033998489	-0.010032054	0	19348.193	0	108.57617	108.59473
3.2145572	-0.0020852089	-0.010016005	0	19365.656	0	108.67578	108.69434
3.2139611	-0.0014891624	-0.0099593978	0	19371.404	0	108.77539	108.79395
3.2141542	-0.0016822815	-0.010066314	0	19374.355	0	108.875	108.89355
3.2134819	-0.0010099411	-0.0099699162	0	19368.941	0	108.97461	108.99316
3.2139206	-0.0014486313	-0.009955517	0	19374.162	0	109.07422	109.09277
3.2126069	-0.00013494492	-0.010015053	0	19375.301	0	109.17383	109.19238
3.2137632	-0.001291275	-0.0099522509	0	19388.74	0	109.27344	109.29199
3.2135963	-0.001124382	-0.010142338	0	19398.027	0	109.37305	109.3916
3.2133341	-0.00086212158	-0.010038674	0	19400.309	0	109.47266	109.49121
3.2130337	-0.00056171417	-0.010044948	0	19398.408	0	109.57227	109.59082
3.2139468	-0.0014748573	-0.010020856	0	19413.973	0	109.67188	109.69043
3.212769	-0.00029706955	-0.0099653266	0	19417.982	0	109.77148	109.79004
3.2129431	-0.00047111511	-0.010089438	0	19418.416	0	109.87109	109.88965
3.2129622	-0.0004901886	-0.010067018	0	19415.746	0	109.9707	109.98926
3.2132626	-0.00079059601	-0.0099944696	0	19413.797	0	110.07031	110.08887
3.2126641	-0.00019216537	-0.0099869594	0	19422.684	0	110.16992	110.18848
3.2129431	-0.00047111511	-0.0099352822	0	19419.205	0	110.26953	110.28809
3.212719	-0.00024700165	-0.0099805752	0	19419.4	0	110.36914	110.3877
3.2121706	0.00030136108	-0.010013714	0	19412.977	0	110.46875	110.4873
3.2122636	0.00020837784	-0.010132344	0	19414.525	0	110.56836	110.58691
3.2125139	-4.196167e-05	-0.010006824	0	19424.014	0	110.66797	110.68652
3.2124925	-2.0503998e-05	-0.010050984	0	19426.342	0	110.76758	110.78613
3.2127047	-0.00023269653	-0.01004073	0	19427.291	0	110.86719	110.88574
3.2126975	-0.00022554398	-0.0099991011	0	19434.021	0	110.9668	110.98535
3.2133079	-0.00083589554	-0.010161557	0	19434.592	0	111.06641	111.08496
3.2124496	2.2411346e-05	-0.010121319	0	19433.586	0	111.16602	111.18457
3.212986	-0.00051403046	-0.010028885	0	19435.248	0	111.26563	111.28418
3.2129478	-0.00047588348	-0.010036651	0	19438.688	0	111.36523	111.38379
3.212707	-0.00023508072	-0.010107605	0	19441.971	0	111.46484	111.4834
3.2116294	0.00084257126	-0.0098916106	0	19443.248	0	111.56445	111.58301
3.2122064	0.0002655983	-0.01000309	0	19445.463	0	111.66406	111.68262
3.2127357	-0.00026369095	-0.010140237	0	19450.746	0	111.76367	111.78223
3.2125068	-3.4809113e-05	-0.010132725	0	19451.885	0	111.86328	111.88184
3.2126236	-0.00015163422	-0.0099282246	0	19449.736	0	111.96289	111.98145
3.2121253	0.00034666061	-0.0099270316	0	19450.783	0	112.0625	112.08105
3.2129574	-0.00048542023	-0.010040727	0	19452.4	0	112.16211	112.18066
3.2115865	0.0008854866	-0.0098231994	0	19441.9	0	112.26172	112.28027
3.2120228	0.0004491806	-0.010015192	0	19441.305	0	112.36133	112.37988
3.2125759	-0.0001039505	-0.0099105239	0	19449.826	0	112.46094	112.47949
3.2128501	-0.00037813187	-0.0099371262	0	19454.438	0	112.56055	112.5791
3.2129931	-0.00052118301	-0.010020993	0	19459.652	0	112.66016	112.67871
3.2126856	-0.00021362305	-0.010055049	0	19466.863	0	112.75977	112.77832
3.2132006	-0.00072860718	-0.010034564	0	19468.031	0	112.85938	112.87793
3.2125926	-0.0001206398	-0.0099221971	0	19466.852	0	112.95898	112.97754
3.212738	-0.00026607513	-0.0099670524	0	19468.303	0	113.05859	113.07715
3.2132816	-0.00080966949	-0.0099313427	0	19477.982	0	113.1582	113.17676
3.2130337	-0.00056171417	-0.0099395504	0	19473.932	0	113.25781	113.27637
3.2130742	-0.00060224533	-0.0099412184	0	19474.73	0	113.35742	113.37598
3.2117844	0.00068759918	-0.0097979838	0	19468.828	0	113.45703	113.47559
3.2124567	1.5258789e-05	-0.010023348	0	19475.623	0	113.55664	113.5752
3.2124615	1.0490417e-05	-0.0098687829	0	19478.141	0	113.65625	113.6748
3.213799	-0.0013270378	-0.0099179801	0	19481.492	0	113.75586	113.77441
3.2124615	1.0490417e-05	-0.009984104	0	19479.945	0	113.85547	113.87402
3.2125282	-5.6266785e-05	-0.009823272	0	19473.498	0	113.95508	113.97363
3.2124996	-2.7656555e-05	-0.0099314526	0	19469.889	0	114.05469	114.07324
3.2119608	0.00051116943	-0.0099265892	0	19469.096	0	114.1543	114.17285
3.212359	0.00011301041	-0.0099977218	0	19474.91	0	114.25391	114.27246
3.2127142	-0.00024223328	-0.010040049	0	19475.322	0	114.35352	114.37207
3.2125211	-4.9114227e-05	-0.0098790089	0	19475.92	0	114.45313	114.47168
3.212347	0.00012493134	-0.0098172156	0	19475.656	0	114.55273	114.57129
3.2117534	0.0007185936	-0.0099988263	0	19470.459	0	114.65234	114.6709
3.2122111	0.00026082993	-0.010056798	0	19471.066	0	114.75195	114.77051
3.2122087	0.00026321411	-0.0098472983	0	19475.566	0	114.85156	114.87012
3.211875	0.00059700012	-0.009948683	0	19479.482	0	114.95117	114.96973
3.2129407	-0.00046873093	-0.009833429	0	19480.426	0	115.05078	115.06934
3.2124949	-2.2888184e-05	-0.0098668011	0	19481.205	0	115.15039	115.16895
3.2132411	-0.00076913834	-0.0099440413	0	19487.357	0	115.25	115.26855
3.2126951	-0.00022315979	-0.0098540243	0	19482.695	0	115.34961	115.36816
3.2135892	-0.0011172295	-0.0099547571	0	19480.225	0	115.44922	115.46777
3.2127166	-0.00024461746	-0.010028403	0	19478.418	0	115.54883	115.56738
3.2125807	-0.00010871887	-0.0099249566	0	19483.586	0	115.64844	115.66699
3.2129216	-0.00044965744	-0.0098554008	0	19487.496	0	115.74805	115.7666
3.2131219	-0.00064992905	-0.009909099	0	19485.813	0	115.84766	115.86621
3.21275	-0.00027799606	-0.010021274	0	19490.664	0	115.94727	115.96582
3.2124162	5.5789948e-05	-0.0098862508	0	19485.031	0	116.04688	116.06543
3.212626	-0.0001540184	-0.00993085	0	19487.158	0	116.14648	116.16504
3.2122397	0.0002322197	-0.0097983927	0	19490.854	0	116.24609	116.26465
3.2123923	7.9631805e-05	-0.0099455602	0	19487.693	0	116.3457	116.36426

Data Acquisition						Time:	116.44629	s	12/20/2016 1:19:20 PM
Axial Displacement	Axial Extensometer	Axial Force	Date
mm	mm/mm	N	d
3.4653044	0.015829097	44461.281	42724